test_001 (week_7.class_0301.class_unittest_learn.TestAdd) ... FAIL
test_002 (week_7.class_0301.class_unittest_learn.TestAdd) ... FAIL
test_003 (week_7.class_0301.class_unittest_learn.TestAdd) ... FAIL
test_004 (week_7.class_0301.class_unittest_learn.TestAdd) ... FAIL
test_two_postive (week_7.class_0301.class_unittest_learn.TestSub) ... ok

======================================================================
FAIL: test_001 (week_7.class_0301.class_unittest_learn.TestAdd)
----------------------------------------------------------------------
Traceback (most recent call last):
  File "D:\2018Python自动化\code\python_14\week_7\class_0301\class_unittest_learn.py", line 65, in test_001
    raise e
  File "D:\2018Python自动化\code\python_14\week_7\class_0301\class_unittest_learn.py", line 62, in test_001
    self.assertEqual(expected,c)
AssertionError: 4 != 3

======================================================================
FAIL: test_002 (week_7.class_0301.class_unittest_learn.TestAdd)
----------------------------------------------------------------------
Traceback (most recent call last):
  File "D:\2018Python自动化\code\python_14\week_7\class_0301\class_unittest_learn.py", line 79, in test_002
    raise e
  File "D:\2018Python自动化\code\python_14\week_7\class_0301\class_unittest_learn.py", line 76, in test_002
    self.assertEqual(expected, c)
AssertionError: 2 != 1

======================================================================
FAIL: test_003 (week_7.class_0301.class_unittest_learn.TestAdd)
----------------------------------------------------------------------
Traceback (most recent call last):
  File "D:\2018Python自动化\code\python_14\week_7\class_0301\class_unittest_learn.py", line 91, in test_003
    raise e
  File "D:\2018Python自动化\code\python_14\week_7\class_0301\class_unittest_learn.py", line 88, in test_003
    self.assertEqual(expected, c)
AssertionError: 1 != -3

======================================================================
FAIL: test_004 (week_7.class_0301.class_unittest_learn.TestAdd)
----------------------------------------------------------------------
Traceback (most recent call last):
  File "D:\2018Python自动化\code\python_14\week_7\class_0301\class_unittest_learn.py", line 102, in test_004
    raise e
  File "D:\2018Python自动化\code\python_14\week_7\class_0301\class_unittest_learn.py", line 99, in test_004
    self.assertEqual(expected, c)
AssertionError: 1 != 0

----------------------------------------------------------------------
Ran 5 tests in 0.002s

FAILED (failures=4)
